Workbook

Sheet CLIENT USER GUIDE
A1: ORRA FIELD READINESS TOOL
A2: Client User Guide
A3: 1. PURPOSE OF THE TOOL
A4: This tool helps you answer two key questions:
B5: What risk management capability do we have?
B6: Is that capability sufficient for our operating context?
A7: It does this by:
B8: Assessing your internal capability (theoretical readiness)
B9: Adjusting this based on your operating environment, activities, and operational complexity, to provide your actual readiness
A10: At the end, the tool provides:
B11: An assessment of your actual readiness, tailored to your operating environment, activities, and country context
B12: Your strengths and weaknesses across key areas (Governance, Risk, Security, Crisis, BCP, People, Operations, Assurance)
B13: The distribution of maturity across your organisation (Governance, Risk, Security, Crisis, BCP, People, Operations, Assurance)
A15: 2. HOW TO USE THE TOOL
A16: Follow these steps in order.
A18: STEP 1 – ASSESSMENT
A19: Go to the Assessment tab.
A20: Answer each question based on current practice across your organisation.
A21: Select one of the following for each question:
B22: No / None = Not in place
B23: Ad hoc = Informal or inconsistent
B24: Partial = Some elements in place but gaps remain
B25: Formal = Defined and generally implemented
B26: Embedded = Fully integrated and consistently applied
B27: N/A = Not applicable
A28: Be realistic. Answer based on what actually happens, not intended practice.
A29: The tool averages all responses and converts the result into a percentage (0–100%).
A30: For example: Mostly “Formal” responses will result in a score of approximately 75%.
A32: STEP 2 – COUNTRY RISK
A33: Go to the Country Risk tab. Enter the countries you operate in. Your Maravi Consultant will complete the risk assessment for each.
A34: The country risk level you operate in affects your overall Actual Readiness score — higher-risk countries require greater capability.
A35: In column A, enter the list of countries in which you operate.
A36: Your Maravi Consultant will complete the risk level for each country using Maravi's proprietary country risk tool.
A37: Your consultant will explain the country risk scores and what they mean for your organisation.
A40: STEP 3 – ACTIVITY AND OPERATIONAL EXPOSURE
A41: Go to the Activity Risk tab.
A42: In Column B, complete the following:
B43: High-risk activity: Select YES if your organisation undertakes higher-risk activities (e.g. enforcement, investigations, high-threat environments). Otherwise select NO.
B44: Operational footprint: Select one:
C45: Single site
...

Sheet Step1. Assessment
A1: STEP 1: ASSESSMENT
A2: Select one response per question. Answer based on what actually happens, not intended practice.
A4: No. | B4: Section | C4: Question | D4: Response | K4: Response | L4: Score | M4: What to select
A5: 1 | B5: Governance | C5: How clearly defined is leadership accountability for risk, security, and crisis management? | D5: Formal | E5: =IF(D5="No / None",0,IF(D5="Ad hoc / Informal",1,IF(D5="Partial / Infrequent",2,IF(D5="Formal",3,IF(D5="Embedded",4,""))))) -> 3 | K5: No / None | L5: 0 | M5: Not defined and not implemented. No clear structure, process, or approach is in place.
A6: 2 | B6: Governance | C6: To what extent is senior management actively engaged in risk and security oversight? | D6: Formal | E6: =IF(D6="No / None",0,IF(D6="Ad hoc / Informal",1,IF(D6="Partial / Infrequent",2,IF(D6="Formal",3,IF(D6="Embedded",4,""))))) -> 3 | K6: Ad hoc / Informal | L6: 1 | M6: Not formally defined, but some informal or inconsistent practice exists. Activities may happen but are unplanned or unreliable.
A7: 3 | B7: Governance | C7: How well integrated are risk and security considerations into organisational decision-making? | D7: Formal | E7: =IF(D7="No / None",0,IF(D7="Ad hoc / Informal",1,IF(D7="Partial / Infrequent",2,IF(D7="Formal",3,IF(D7="Embedded",4,""))))) -> 3 | K7: Partial / Infrequent | L7: 2 | M7: Some elements exist but are incomplete, inconsistently applied, or gaps remain in practice.
A8: 4 | B8: Governance | C8: To what extent are roles and responsibilities for risk and security clearly defined across the organisation? | D8: Formal | E8: =IF(D8="No / None",0,IF(D8="Ad hoc / Informal",1,IF(D8="Partial / Infrequent",2,IF(D8="Formal",3,IF(D8="Embedded",4,""))))) -> 3 | K8: Formal | L8: 3 | M8: Formally defined and consistently implemented across most of the organisation. Processes are clearly documented and communicated.
A9: 5 | B9: Governance | C9: How effectively are resources allocated to risk, security, and resilience functions? | D9: Formal | E9: =IF(D9="No / None",0,IF(D9="Ad hoc / Informal",1,IF(D9="Partial / Infrequent",2,IF(D9="Formal",3,IF(D9="Embedded",4,""))))) -> 3 | K9: Embedded | L9: 4 | M9: Fully integrated and consistently applied across the organisation. Routinely used in decision-making and continuously improved.
A10: 6 | B10: Risk | C10: How developed and consistently applied is your organisation-wide risk assessment process? | D10: Formal | E10: =IF(D10="No / None",0,IF(D10="Ad hoc / Informal",1,IF(D10="Partial / Infrequent",2,IF(D10="Formal",3,IF(D10="Embedded",4,""))))) -> 3 | K10: N/A | L10: – | M10: Not applicable. Use only where a question genuinely does not apply — not as a substitute for No / None.
A11: 7 | B11: Risk | C11: How well defined and standardised is your risk assessment methodology? | D11: Formal | E11: =IF(D11="No / None",0,IF(D11="Ad hoc / Informal",1,IF(D11="Partial / Infrequent",2,IF(D11="Formal",3,IF(D11="Embedded",4,""))))) -> 3
A12: 8 | B12: Risk | C12: How frequently are risk assessments conducted and updated? | D12: Formal | E12: =IF(D12="No / None",0,IF(D12="Ad hoc / Informal",1,IF(D12="Partial / Infrequent",2,IF(D12="Formal",3,IF(D12="Embedded",4,""))))) -> 3
A13: 9 | B13: Risk | C13: How comprehensive and current is your risk register? | D13: Formal | E13: =IF(D13="No / None",0,IF(D13="Ad hoc / Informal",1,IF(D13="Partial / Infrequent",2,IF(D13="Formal",3,IF(D13="Embedded",4,""))))) -> 3
A14: 10 | B14: Risk | C14: To what extent is the risk register actively used in decision-making? | D14: Formal | E14: =IF(D14="No / None",0,IF(D14="Ad hoc / Informal",1,IF(D14="Partial / Infrequent",2,IF(D14="Formal",3,IF(D14="Embedded",4,""))))) -> 3
A15: 11 | B15: Risk | C15: How clearly are risk owners assigned and held accountable? | D15: Formal | E15: =IF(D15="No / None",0,IF(D15="Ad hoc / Informal",1,IF(D15="Partial / Infrequent",2,IF(D15="Formal",3,IF(D15="Embedded",4,""))))) -> 3
A16: 12 | B16: Risk | C16: How systematically are risks monitored and reviewed over time? | D16: Formal | E16: =IF(D16="No / None",0,IF(D16="Ad hoc / Informal",1,IF(D16="Partial / Infrequent",2,IF(D16="Formal",3,IF(D16="Embedded",4,""))))) -> 3
A17: 13 | B17: Security | C17: How comprehensive and implemented is your organisation-wide security policy? | D17: Formal | E17: =IF(D17="No / None",0,IF(D17="Ad hoc / Informal",1,IF(D17="Partial / Infrequent",2,IF(D17="Formal",3,IF(D17="Embedded",4,""))))) -> 3
A18: 14 | B18: Security | C18: How well developed are country or site-specific security plans? | D18: Formal | E18: =IF(D18="No / None",0,IF(D18="Ad hoc / Informal",1,IF(D18="Partial / Infrequent",2,IF(D18="Formal",3,IF(D18="Embedded",4,""))))) -> 3
A19: 15 | B19: Security | C19: How regularly are security plans reviewed and updated? | D19: Formal | E19: =IF(D19="No / None",0,IF(D19="Ad hoc / Informal",1,IF(D19="Partial / Infrequent",2,IF(D19="Formal",3,IF(D19="Embedded",4,""))))) -> 3
A20: 16 | B20: Security | C20: How effectively are security risks assessed at the field level? | D20: Formal | E20: =IF(D20="No / None",0,IF(D20="Ad hoc / Informal",1,IF(D20="Partial / Infrequent",2,IF(D20="Formal",3,IF(D20="Embedded",4,""))))) -> 3
A21: 17 | B21: Security | C21: How robust are access controls and physical security measures across locations? | D21: Formal | E21: =IF(D21="No / None",0,IF(D21="Ad hoc / Informal",1,IF(D21="Partial / Infrequent",2,IF(D21="Formal",3,IF(D21="Embedded",4,""))))) -> 3
A22: 18 | B22: Security | C22: How developed are journey management procedures? | D22: Formal | E22: =IF(D22="No / None",0,IF(D22="Ad hoc / Informal",1,IF(D22="Partial / Infrequent",2,IF(D22="Formal",3,IF(D22="Embedded",4,""))))) -> 3
... A59: 55 | B59: Assurance | C59: How effectively does the organisation adapt its systems based on emerging risks? | D59: Formal | E59: =IF(D59="No / None",0,IF(D59="Ad hoc / Informal",1,IF(D59="Partial / Infrequent",2,IF(D59="Formal",3,IF(D59="Embedded",4,""))))) -> 3

Sheet Step2. Country Risk
A1: STEP 2: COUNTRY RISK
A2: Enter the name of each country you operate in (one per row). Your Maravi Consultant will assess the risk level for each country.
A3: Country risk scores will be explained by your consultant and will affect your overall Actual Readiness score.
A5: Country | B5: Risk Level | C5: Multiplier | D5: Adjusted Readiness | E5: Status | F5: Impact
A6: malawi | B6: Severe | C6: =IF(B6="Low",1,IF(B6="Moderate",1.2,IF(B6="Elevated",1.5,IF(B6="Severe",1.8,"")))) -> 1.8 | D6: =IF(C6="", "", 'Step4. Dashboard'!$B$11/C6) -> 0.41666667 | E6: =IF(D6="","",IF(D6<0.5,"Not sufficient",IF(D6<0.7,"Needs strengthening","Suitable"))) -> Not sufficient | F6: =IF(B5="Low",0,IF(B6="Moderate",0.1,IF(B6="Elevated",0.2,IF(B6="Severe",0.3,"")))) -> 0.3
C7: =IF(B7="Low",1,IF(B7="Moderate",1.2,IF(B7="Elevated",1.5,IF(B7="Severe",1.8,"")))) | D7: =IF(C7="", "", 'Step4. Dashboard'!$B$11/C7) | E7: =IF(D7="","",IF(D7<0.5,"Not sufficient",IF(D7<0.7,"Needs strengthening","Suitable"))) | F7: =IF(B6="Low",0,IF(B7="Moderate",0.1,IF(B7="Elevated",0.2,IF(B7="Severe",0.3,""))))
C8: =IF(B8="Low",1,IF(B8="Moderate",1.2,IF(B8="Elevated",1.5,IF(B8="Severe",1.8,"")))) | D8: =IF(C8="", "", 'Step4. Dashboard'!$B$11/C8) | E8: =IF(D8="","",IF(D8<0.5,"Not sufficient",IF(D8<0.7,"Needs strengthening","Suitable"))) | F8: =IF(B7="Low",0,IF(B8="Moderate",0.1,IF(B8="Elevated",0.2,IF(B8="Severe",0.3,""))))
C9: =IF(B9="Low",1,IF(B9="Moderate",1.2,IF(B9="Elevated",1.5,IF(B9="Severe",1.8,"")))) | D9: =IF(C9="", "", 'Step4. Dashboard'!$B$11/C9) | E9: =IF(D9="","",IF(D9<0.5,"Not sufficient",IF(D9<0.7,"Needs strengthening","Suitable")))
C10: =IF(B10="Low",1,IF(B10="Moderate",1.2,IF(B10="Elevated",1.5,IF(B10="Severe",1.8,"")))) | D10: =IF(C10="", "", 'Step4. Dashboard'!$B$11/C10) | E10: =IF(D10="","",IF(D10<0.5,"Not sufficient",IF(D10<0.7,"Needs strengthening","Suitable")))
C11: =IF(B11="Low",1,IF(B11="Moderate",1.2,IF(B11="Elevated",1.5,IF(B11="Severe",1.8,"")))) | D11: =IF(C11="", "", 'Step4. Dashboard'!$B$11/C11) | E11: =IF(D11="","",IF(D11<0.5,"Not sufficient",IF(D11<0.7,"Needs strengthening","Suitable")))
C12: =IF(B12="Low",1,IF(B12="Moderate",1.2,IF(B12="Elevated",1.5,IF(B12="Severe",1.8,"")))) | D12: =IF(C12="", "", 'Step4. Dashboard'!$B$11/C12) | E12: =IF(D12="","",IF(D12<0.5,"Not sufficient",IF(D12<0.7,"Needs strengthening","Suitable")))
C13: =IF(B13="Low",1,IF(B13="Moderate",1.2,IF(B13="Elevated",1.5,IF(B13="Severe",1.8,"")))) | D13: =IF(C13="", "", 'Step4. Dashboard'!$B$11/C13) | E13: =IF(D13="","",IF(D13<0.5,"Not sufficient",IF(D13<0.7,"Needs strengthening","Suitable")))
C14: =IF(B14="Low",1,IF(B14="Moderate",1.2,IF(B14="Elevated",1.5,IF(B14="Severe",1.8,"")))) | D14: =IF(C14="", "", 'Step4. Dashboard'!$B$11/C14) | E14: =IF(D14="","",IF(D14<0.5,"Not sufficient",IF(D14<0.7,"Needs strengthening","Suitable")))
C15: =IF(B15="Low",1,IF(B15="Moderate",1.2,IF(B15="Elevated",1.5,IF(B15="Severe",1.8,"")))) | D15: =IF(C15="", "", 'Step4. Dashboard'!$B$11/C15) | E15: =IF(D15="","",IF(D15<0.5,"Not sufficient",IF(D15<0.7,"Needs strengthening","Suitable")))
D16: =IF(C16="", "", 'Step4. Dashboard'!$B$11/C16) | E16: =IF(D16="","",IF(D16<0.5,"Not sufficient",IF(D16<0.7,"Needs strengthening","Suitable")))
D17: =IF(C17="", "", 'Step4. Dashboard'!$B$11/C17) | E17: =IF(D17="","",IF(D17<0.5,"Not sufficient",IF(D17<0.7,"Needs strengthening","Suitable")))
D18: =IF(C18="", "", 'Step4. Dashboard'!$B$11/C18) | E18: =IF(D18="","",IF(D18<0.5,"Not sufficient",IF(D18<0.7,"Needs strengthening","Suitable")))
D19: =IF(C19="", "", 'Step4. Dashboard'!$B$11/C19) | E19: =IF(D19="","",IF(D19<0.5,"Not sufficient",IF(D19<0.7,"Needs strengthening","Suitable")))
D20: =IF(C20="", "", 'Step4. Dashboard'!$B$11/C20) | E20: =IF(D20="","",IF(D20<0.5,"Not sufficient",IF(D20<0.7,"Needs strengthening","Suitable")))
D21: =IF(C21="", "", 'Step4. Dashboard'!$B$11/C21) | E21: =IF(D21="","",IF(D21<0.5,"Not sufficient",IF(D21<0.7,"Needs strengthening","Suitable")))
D22: =IF(C22="", "", 'Step4. Dashboard'!$B$11/C22) | E22: =IF(D22="","",IF(D22<0.5,"Not sufficient",IF(D22<0.7,"Needs strengthening","Suitable")))
D23: =IF(C23="", "", 'Step4. Dashboard'!$B$11/C23) | E23: =IF(D23="","",IF(D23<0.5,"Not sufficient",IF(D23<0.7,"Needs strengthening","Suitable")))
D24: =IF(C24="", "", 'Step4. Dashboard'!$B$11/C24) | E24: =IF(D24="","",IF(D24<0.5,"Not sufficient",IF(D24<0.7,"Needs strengthening","Suitable")))
D25: =IF(C25="", "", 'Step4. Dashboard'!$B$11/C25) | E25: =IF(D25="","",IF(D25<0.5,"Not sufficient",IF(D25<0.7,"Needs strengthening","Suitable")))
D26: =IF(C26="", "", 'Step4. Dashboard'!$B$11/C26) | E26: =IF(D26="","",IF(D26<0.5,"Not sufficient",IF(D26<0.7,"Needs strengthening","Suitable")))
D27: =IF(C27="", "", 'Step4. Dashboard'!$B$11/C27) | E27: =IF(D27="","",IF(D27<0.5,"Not sufficient",IF(D27<0.7,"Needs strengthening","Suitable")))

Sheet Step3. Activity & Op Exposure
A1: STEP 3: ACTIVITY & OPERATIONAL EXPOSURE
A2: Select your answers in column B.
A4: Question | B4: Your Response | C4: Multiplier
A5: Does your organisation undertake high-risk activities? High-risk activities include work in high-threat environments, enforcement or investigation activities, or operations where staff are exposed to significant security, safety, travel or reputational risks. | B5: Yes | C5: =IF(B5="Yes",1.8,1) -> 1.8
A6: How complex is your operational footprint? This reflects how widely and complexly your operations are delivered. Single site: One primary operational location Multiple sites: Several locations within one country Multi-country / remote operations: Activities across multiple countries or remotely managed teams | B6: Multi-country / remote operations | C6: =IF(B6="Single site",1,IF(B6="Multiple sites (same country)",1.2,IF(B6="Multi-country / remote operations",1.4,""))) -> 1.4
A7: Exposure Adjustment Factor | C7: =C5 * C6 -> 2.52

Sheet Step4. Dashboard
A1: STEP 4: DASHBOARD
A2: Results are calculated automatically. No input required on this tab.
A3: Actual readiness reflects your capability adjusted for context — including the nature of your activities, operational complexity, and the countries you work in.
A10: Key Metrics | B10: Result | C10: Explanation
A11: Theoretical Readiness Score | B11: =IFERROR(AVERAGE(B28:B35)/100,0) -> 0.75
A12: Theoretical Readiness Level | B12: =IF(B11<0.3,"Critical",IF(B11<0.5,"Fragile",IF(B11<0.7,"Developing",IF(B11<0.85,"Operational","Mature")))) -> Operational
A13: Actual Readiness (adjusted for activity, complexity, and country risk) | B13: =IFERROR(B11/MIN('Step3. Activity & Op Exposure'!C7*IF(MAX('Step2. Country Risk'!C6:C22)>=1,MAX('Step2. Country Risk'!C6:C22),1),2.5),0) -> 0.3
A14: Actual Readiness Level (adjusted for context: see below) | B14: =IF(B13<0.3,"Critical",IF(B13<0.5,"Fragile",IF(B13<0.7,"Developing",IF(B13<0.85,"Operational","Mature")))) -> Fragile
A15: Summary description | B15: =IF(B13<0.5,"Not sufficient for operating context and activities",IF(B13<0.7,"Capability present but requires strengthening","Capability broadly appropriate for current risk profile")) -> Not sufficient for operating context and activities
A18: Count of questionnaire responses | B18: Count
A19: No / None | B19: =COUNTIF('Step1. Assessment'!D5:D59,"No / None") -> 0
A20: Ad hoc | B20: =COUNTIF('Step1. Assessment'!D5:D59,"Ad hoc / Informal") -> 0
A21: Partial | B21: =COUNTIF('Step1. Assessment'!D5:D59,"Partial / Infrequent") -> 0
A22: Formal | B22: =COUNTIF('Step1. Assessment'!D5:D59,"Formal") -> 55
A23: Embedded | B23: =COUNTIF('Step1. Assessment'!D5:D59,"Embedded") -> 0
A24: N/A | B24: =COUNTIF('Step1. Assessment'!D5:D59,"N/A") -> 0
A27: Section | B27: Score | C27: Priority
A28: Governance | B28: =IFERROR(AVERAGEIF('Step1. Assessment'!B:B,"Governance",'Step1. Assessment'!E:E)/4,0)*100 -> 75 | C28: =IF(B28<50,"High",IF(B28<=70,"Medium","Low")) -> Low
A29: Risk | B29: =IFERROR(AVERAGEIF('Step1. Assessment'!B:B,"Risk",'Step1. Assessment'!E:E)/4,0)*100 -> 75 | C29: =IF(B29<50,"High",IF(B29<=70,"Medium","Low")) -> Low
A30: Security | B30: =IFERROR(AVERAGEIF('Step1. Assessment'!B:B,"Security",'Step1. Assessment'!E:E)/4,0)*100 -> 75 | C30: =IF(B30<50,"High",IF(B30<=70,"Medium","Low")) -> Low
A31: Crisis | B31: =IFERROR(AVERAGEIF('Step1. Assessment'!B:B,"Crisis",'Step1. Assessment'!E:E)/4,0)*100 -> 75 | C31: =IF(B31<50,"High",IF(B31<=70,"Medium","Low")) -> Low
A32: BCP | B32: =IFERROR(AVERAGEIF('Step1. Assessment'!B:B,"BCP",'Step1. Assessment'!E:E)/4,0)*100 -> 75 | C32: =IF(B32<50,"High",IF(B32<=70,"Medium","Low")) -> Low
A33: People | B33: =IFERROR(AVERAGEIF('Step1. Assessment'!B:B,"People",'Step1. Assessment'!E:E)/4,0)*100 -> 75 | C33: =IF(B33<50,"High",IF(B33<=70,"Medium","Low")) -> Low
A34: Operations | B34: =IFERROR(AVERAGEIF('Step1. Assessment'!B:B,"Operations",'Step1. Assessment'!E:E)/4,0)*100 -> 75 | C34: =IF(B34<50,"High",IF(B34<70,"Medium","Low")) -> Low
A35: Assurance | B35: =IFERROR(AVERAGEIF('Step1. Assessment'!B:B,"Assurance",'Step1. Assessment'!E:E)/4,0)*100 -> 75 | C35: =IF(B35<50,"High",IF(B35<70,"Medium","Low")) -> Low

Sheet STEP5. Acting on Your Results
A1: STEP 5: ACTING ON YOUR RESULTS
A3: Next Steps
A4: The priority areas identified above indicate where strengthening efforts should be focused in order to align capability with operational demands. Next steps should involve reviewing these areas in more detail in conjunction with Maravi and determining where improvements will have the greatest impact on operational readiness. This may include clarifying roles and responsibilities, strengthening processes, increasing consistency of implementation, and ensuring systems are appropriately scaled to the organisation’s operating environment. The results of this assessment are intended to support informed decision-making and can be used as the basis for further planning and capability development.
A9: Executive Summary
A10: ="Theoretical readiness: " & TEXT('Step4. Dashboard'!B11,"0%")& " | Actual readiness: " & TEXT('Step4. Dashboard'!B13,"0%") -> Theoretical readiness: 75% | Actual readiness: 30%
A11: ="Actual readiness level: " & 'Step4. Dashboard'!B12 & " | Overall assessment: " & 'Step4. Dashboard'!B15 -> Actual readiness level: Operational | Overall assessment: Not sufficient for operating context and activities
A12: =IF('Step4. Dashboard'!B13<'Step4. Dashboard'!B11,"The actual readiness score is lower than the theoretical score, indicating that current capability may not be sufficient for the organisation’s level of operational exposure.","Actual readiness is broadly aligned with current capability.") -> The actual readiness score is lower than the theoretical score, indicating that current capability may not be sufficient for the organisation’s level of operational exposure.
A14: What Your Score Means
A15: A significant difference between base and adjusted readiness typically indicates that the level of operational exposure exceeds current organisational capability. This does not necessarily indicate weak systems, but rather that the demands of the operating context are higher than those systems are currently designed to support.
A17: The adjusted readiness score reflects the demands of your operating environment, including the nature of your activities and the complexity of your operational footprint. Higher-risk activities and more complex or distributed operations increase the level of capability required to operate effectively and safely.
A19: Using Your Results: Priority Areas
A20: The results should be used to identify gaps between current capability and operational requirements. Particular attention should be given to areas where capability is less developed or where systems are not consistently applied across the organisation.
A22: =IF(COUNTIF('Step4. Dashboard'!C28:C35,"High")=8,"All core capability areas have been identified as high priority,indicating that organisational capability is not currently aligned with operational demands. A broad-based strengthening approach is required.","These areas represent the most important opportunities to strengthen capability in relation to your current operating context.") -> These areas represent the most important opportunities to strengthen capability in relation to your current operating context.
A23: ="1. " &'Step4. Dashboard'!A28 -> 1. Governance | C23: Strengthen leadership accountability and oversight
A24: ="2. " &'Step4. Dashboard'!A29 -> 2. Risk | C24: Formalise and consistently apply risk assessment processes
A25: ="3. " &'Step4. Dashboard'!A30 -> 3. Security | C25: Strengthen security planning and incident reporting
A26: ="4. " &'Step4. Dashboard'!A31 -> 4. Crisis | C26: Establish and test crisis management capability
A27: ="5. " &'Step4. Dashboard'!A32 -> 5. BCP | C27: Develop business continuity planning and recovery capability
A28: ="6. " &'Step4. Dashboard'!A33 -> 6. People | C28: Improve staff training and preparedness for higher-risk environments
A29: ="7. " &'Step4. Dashboard'!A34 -> 7. Operations | C29: Standardise operational processes and strengthen supervision
A30: ="8. " &'Step4. Dashboard'!A35 -> 8. Assurance | C30: Strengthen review processes and integration of lessons learned
A32: Getting Started
A33: To discuss your results, explore what they mean in practice, and agree priorities for strengthening readiness, please contact your Maravi consultant:
A34: [Consultant name] · [Email address] · [Phone number]
A35: www.maravi.co.uk · info@maravi.co.uk

Sheet Copyright
A1: Copyright
A3: © Maravi Group Ltd. All rights reserved.
A4: This tool and its contents are the intellectual property of Maravi Group Ltd. It may not be reproduced, distributed, or used without prior written consent.
A5: www.maravi.co.uk

Sheet About Maravi
A1: About Maravi Group
A3: Maravi Group provides specialist risk, security, and resilience advisory services to organisations operating in complex and challenging environments.
A4: We help organisations understand and manage operational risk, strengthen security and crisis management capability, and build resilience across their operations.
A5: This tool was developed by Maravi Group as part of our approach to supporting clients through structured, evidence-based readiness assessment.
A7: Contact
A8: www.maravi.co.uk · info@maravi.co.uk
